<mujoco><option>timestep="0.1"</option><worldbody><light diffuse=".5 .5 .5" dir="0 0 1" pos="0 0 3" /><geom name="floor" size="2 2 0.1" type="plane" /><body><freejoint name="root" /><geom name="head" pos="0 0 0.4" rgba="1 .75 0 1" size="0.3 0.2 0.2" type="box" /><body name="leg1"><geom pos="0.2 0.25 0.3" size="0.05 0.05 0.15" type="box" /><joint axis="0 1 0" limited="true" name="leg1Hinge" pos="0 0 0.5" range="-10 10" /></body><body name="leg2"><geom pos="-0.2 0.25 0.3" size="0.05 0.05 0.15" type="box" /><joint axis="0 1 0" limited="true" name="leg2Hinge" pos="0 0 0.5" range="-10 10" /></body><body name="leg3"><geom name="leg3" pos="0.2 -0.25 0.3" size="0.05 0.05 0.15" type="box" /><joint axis="0 1 0" limited="true" name="leg3Hinge" pos="0 0 0.5" range="-10 10" /></body><body name="leg4"><geom name="leg4" pos="-0.2 -0.25 0.3" size="0.05 0.05 0.15" type="box" /><joint axis="0 1 0" limited="true" name="leg4Hinge" pos="0 0 0.5" range="-10 10" /></body></body></worldbody><actuator><motor gear="50" joint="leg1Hinge" name="leg1Hinge" /><motor gear="50" joint="leg2Hinge" name="leg2Hinge" /><motor gear="50" joint="leg3Hinge" name="leg3Hinge" /><motor gear="50" joint="leg4Hinge" name="leg4Hinge" /></actuator></mujoco>